Workbook

Sheet JANUARY 2025
B1: Tourism Attraction Visitor Record | P1: (VAR 1)
B2: ( This recording form can be used instead of just counting the visitors )
F4: Month/Year: | H4: 45658
F5: Name of City/Municipality: | H5: BALAYAN, BATANGAS
F6: Name of attraction/ Spot:
E8: Type of Tourism Attraction:
B10: DAYTOUR ARRIVALS
B11: Date | E11: *** Place of Residence | N11: * Grand Total Number of Visitors
C12: Accommodation Establishment | E12: Philippines | K12: Foreign Country Residence
E13: This province | H13: Other Province
D14: Attraction Code | E14: Male | F14: Female | G14: Total | H14: Male | I14: Female | J14: Total | K14: Male | L14: Female | M14: Total | N14: Male | O14: Female | P14: Total
B15: 1 | C15: AURORA RESORT | D15: NO RECORD SUBMITTED | G15: =SUM(E15:F15) -> 0 | J15: =SUM(H15:I15) -> 0 | M15: =SUM(K15:L15) -> 0 | N15: =SUM(E15,H15,K15) -> 0 | O15: =SUM(F15,I15,L15) -> 0 | P15: =SUM(G15,J15,M15) -> 0
B16: 2 | C16: ALTINA BEACH HOUSE | D16: NO RECORD SUBMITTED | G16: =SUM(E16:F16) -> 0 | J16: =SUM(H16:I16) -> 0 | M16: =SUM(K16:L16) -> 0 | N16: =SUM(E16,H16,K16) -> 0 | O16: =SUM(F16,I16,L16) -> 0 | P16: =SUM(G16,J16,M16) -> 0
B17: 3 | C17: CHRISOVA RESORT | E17: 149 | F17: 129 | G17: =SUM(E17:F17) -> 278 | J17: =SUM(H17:I17) -> 0 | M17: =SUM(K17:L17) -> 0 | N17: =SUM(E17,H17,K17) -> 149 | O17: =SUM(F17,I17,L17) -> 129 | P17: =SUM(G17,J17,M17) -> 278
B18: 4 | C18: DARLING ANGEL RESORT | E18: 184 | F18: 122 | G18: =SUM(E18:F18) -> 306 | J18: =SUM(H18:I18) -> 0 | M18: =SUM(K18:L18) -> 0 | N18: =SUM(E18,H18,K18) -> 184 | O18: =SUM(F18,I18,L18) -> 122 | P18: =SUM(G18,J18,M18) -> 306
B19: 5 | C19: EASTERN STAR RESORT & INNS INC | E19: 0 | F19: 0 | G19: =SUM(E19:F19) -> 0 | H19: 0 | I19: 0 | J19: 0 | M19: =SUM(K19:L19) -> 0 | N19: =SUM(E19,H19,K19) -> 0 | O19: =SUM(F19,I19,L19) -> 0 | P19: =SUM(G19,J19,M19) -> 0
B20: 6 | C20: KING & QUEEN RESORT | D20: NO RECORD SUBMITTED | G20: =SUM(E20:F20) -> 0 | J20: =SUM(H20:I20) -> 0 | M20: =SUM(K20:L20) -> 0 | N20: =SUM(E20,H20,K20) -> 0 | O20: =SUM(F20,I20,L20) -> 0 | P20: =SUM(G20,J20,M20) -> 0
B21: 7 | C21: LA GEORGINA RESORT | D21: NO RECORD SUBMITTED | G21: =SUM(E21:F21) -> 0 | J21: =SUM(H21:I21) -> 0 | M21: =SUM(K21:L21) -> 0 | N21: =SUM(E21,H21,K21) -> 0 | O21: =SUM(F21,I21,L21) -> 0 | P21: =SUM(G21,J21,M21) -> 0
B22: 8 | C22: LA PISCINA DI CONCEPCION RESORT | E22: 969 | F22: 965 | G22: =SUM(E22:F22) -> 1934 | H22: 0 | I22: 0 | J22: =SUM(H22:I22) -> 0 | M22: =SUM(K22:L22) -> 0 | N22: =SUM(E22,H22,K22) -> 969 | O22: =SUM(F22,I22,L22) -> 965 | P22: =SUM(G22,J22,M22) -> 1934
B23: 9 | C23: MALABANAN SWIMMING POOL | D23: NO RECORD SUBMITTED | G23: =SUM(E23:F23) -> 0 | J23: =SUM(H23:I23) -> 0 | M23: =SUM(K23:L23) -> 0 | N23: =SUM(E23,H23,K23) -> 0 | O23: =SUM(F23,I23,L23) -> 0 | P23: =SUM(G23,J23,M23) -> 0
B24: 10 | C24: MY PLACE RESORT & PAVILLION | G24: =SUM(E24:F24) -> 0 | J24: =SUM(H24:I24) -> 0 | M24: =SUM(K24:L24) -> 0 | N24: =SUM(E24,H24,K24) -> 0 | O24: =SUM(F24,I24,L24) -> 0 | P24: =SUM(G24,J24,M24) -> 0
B25: 11 | C25: VADZ CASTILLO RESIDENCE | D25: 0 | E25: 57 | F25: 45 | G25: =SUM(E25:F25) -> 102 | J25: 102 | M25: =SUM(K25:L25) -> 0 | N25: =SUM(E25,H25,K25) -> 57 | O25: =SUM(F25,I25,L25) -> 45 | P25: =SUM(G25,J25,M25) -> 204
B26: 12 | C26: VIKTORIA'S GARDEN RESORT (NOT OPERATIONAL) | E26: 184 | F26: 122 | G26: =SUM(E26:F26) -> 306 | J26: =SUM(H26:I26) -> 0 | M26: =SUM(K26:L26) -> 0 | N26: =SUM(E26,H26,K26) -> 184 | O26: =SUM(F26,I26,L26) -> 122 | P26: =SUM(G26,J26,M26) -> 306
B27: 13 | C27: VILLA BEADOY RESORT & PAVILLION | E27: 209 | F27: 236 | G27: =SUM(E27:F27) -> 445 | J27: =SUM(H27:I27) -> 0 | M27: =SUM(K27:L27) -> 0 | N27: =SUM(E27,H27,K27) -> 209 | O27: =SUM(F27,I27,L27) -> 236 | P27: =SUM(G27,J27,M27) -> 445
B28: 14 | C28: VILLA SCARLET GARDEN RESORT | E28: 54 | F28: 57 | G28: =SUM(E28:F28) -> 111 | J28: =SUM(H28:I28) -> 0 | M28: =SUM(K28:L28) -> 0 | N28: =SUM(E28,H28,K28) -> 54 | O28: =SUM(F28,I28,L28) -> 57 | P28: =SUM(G28,J28,M28) -> 111
C30: TOURIST ATTRACTIONS
B31: 1 | C31: ATHENA RIVER RESORT | E31: 44 | F31: 29 | G31: =SUM(E31:F31) -> 73 | J31: =SUM(H31:I31) -> 0 | M31: =SUM(K31:L31) -> 0 | N31: =SUM(E31,H31,K31) -> 44 | O31: =SUM(F31,I31,L31) -> 29 | P31: =SUM(G31,J31,M31) -> 73
B32: 2 | C32: BALAYAN BAYWALK | G32: 7750 | J32: =SUM(H32:I32) -> 0 | M32: =SUM(K32:L32) -> 0 | N32: =SUM(E32,H32,K32) -> 0 | O32: =SUM(F32,I32,L32) -> 0 | P32: =SUM(G32,J32,M32) -> 7750
B33: 3 | C33: EL SENOR TRES CAIDAS CHAPEL | G33: 2000 | J33: =SUM(H33:I33) -> 0 | M33: =SUM(K33:L33) -> 0 | N33: =SUM(E33,H33,K33) -> 0 | O33: =SUM(F33,I33,L33) -> 0 | P33: =SUM(G33,J33,M33) -> 2000
B34: 4 | C34: IMMACULATE CONCEPTION PARISH | G34: 11890 | J34: =SUM(H34:I34) -> 0 | M34: =SUM(K34:L34) -> 0 | N34: =SUM(E34,H34,K34) -> 0 | O34: =SUM(F34,I34,L34) -> 0 | P34: =SUM(G34,J34,M34) -> 11890
B35: 5 | C35: MAGSINO CHOKDEE ECOCARE FARM | E35: 38 | F35: 62 | G35: 100 | J35: =SUM(H35:I35) -> 0 | M35: =SUM(K35:L35) -> 0 | N35: =SUM(E35,H35,K35) -> 38 | O35: =SUM(F35,I35,L35) -> 62 | P35: =SUM(G35,J35,M35) -> 100
B36: 6 | C36: MOLINO NATURE PARK | G36: 2589 | J36: =SUM(H36:I36) -> 0 | M36: =SUM(K36:L36) -> 0 | N36: =SUM(E36,H36,K36) -> 0 | O36: =SUM(F36,I36,L36) -> 0 | P36: =SUM(G36,J36,M36) -> 2589
C37: EVENTS | G37: =SUM(E37:F37) -> 0 | J37: =SUM(H37:I37) -> 0 | M37: =SUM(K37:L37) -> 0 | N37: =SUM(E37,H37,K37) -> 0 | O37: =SUM(F37,I37,L37) -> 0 | P37: =SUM(G37,J37,M37) -> 0
B38: Total of this Month **** | E38: =SUM(E15:E37) -> 1888 | F38: =SUM(F15:F37) -> 1767 | G38: =SUM(G15:G37) -> 27884 | H38: =SUM(H15:H37) -> 0 | I38: =SUM(I15:I37) -> 0 | J38: =SUM(J15:J37) -> 102 | K38: =SUM(K15:K37) -> 0 | L38: =SUM(L15:L37) -> 0 | ... P38: =SUM(P15:P37) -> 27986
B39: Note: *Total number must be recorded, ** Sex & ***Residence entries are optional. Total number of this month must be reported.
B40: OVERNIGHT ARRIVALS
B41: Date | D41: 45658
C42: Accommodation Establishment | D42: Attraction Code | E42: (5) Number of Guests Check IN (unit: visitors) | F42: (6) Number of Guests staying over-night (Guest Nights) | G42: (7) Number of Rooms Occupied by Guests (unit: rooms) | H42: Average Guest/Night | I42: Average Room Occupancy Rate
B45: 1 | C45: ALVEZ LODGE & RESTAURANT | E45: 842 | F45: 842 | G45: 421
B46: 2 | C46: EASTERN STAR RESORT & INNS INC | E46: 860 | F46: 0 | G46: 0
...

Sheet FEBRUARY 2025
B1: Tourism Attraction Visitor Record | P1: (VAR 1)
B2: ( This recording form can be used instead of just counting the visitors )
F4: Month/Year: | H4: 45689
F5: Name of City/Municipality: | H5: BALAYAN, BATANGAS
F6: Name of attraction/ Spot:
E8: Type of Tourism Attraction:
B10: DAYTOUR ARRIVALS
B11: Date | E11: *** Place of Residence | N11: * Grand Total Number of Visitors
C12: Accommodation Establishment | E12: Philippines | K12: Foreign Country Residence
E13: This province | H13: Other Province
D14: Attraction Code | E14: Male | F14: Female | G14: Total | H14: Male | I14: Female | J14: Total | K14: Male | L14: Female | M14: Total | N14: Male | O14: Female | P14: Total
B15: 1 | C15: AURORA RESORT | D15: NO RECORD SUBMITTED | M15: =SUM(K15:L15) -> 0 | N15: =SUM(E15,H15,K15) -> 0 | O15: =SUM(F15,I15,L15) -> 0 | P15: =SUM(G15,J15,M15) -> 0
B16: 2 | C16: ALTINA BEACH HOUSE | D16: NO RECORD SUBMITTED | M16: =SUM(K16:L16) -> 0 | N16: =SUM(E16,H16,K16) -> 0 | O16: =SUM(F16,I16,L16) -> 0 | P16: =SUM(G16,J16,M16) -> 0
B17: 3 | C17: CHRISOVA RESORT | E17: 51 | F17: 34 | G17: 85 | M17: =SUM(K17:L17) -> 0 | N17: =SUM(E17,H17,K17) -> 51 | O17: =SUM(F17,I17,L17) -> 34 | P17: =SUM(G17,J17,M17) -> 85
B18: 4 | C18: DARLING ANGEL RESORT | E18: 161 | F18: 99 | G18: 247 | M18: =SUM(K18:L18) -> 0 | N18: =SUM(E18,H18,K18) -> 161 | O18: =SUM(F18,I18,L18) -> 99 | P18: =SUM(G18,J18,M18) -> 247
B19: 5 | C19: EASTERN STAR RESORT & INNS INC | G19: 860 | M19: =SUM(K19:L19) -> 0 | N19: =SUM(E19,H19,K19) -> 0 | O19: =SUM(F19,I19,L19) -> 0 | P19: =SUM(G19,J19,M19) -> 860
B20: 6 | C20: KING & QUEEN RESORT | D20: NO RECORD SUBMITTED | M20: =SUM(K20:L20) -> 0 | N20: =SUM(E20,H20,K20) -> 0 | O20: =SUM(F20,I20,L20) -> 0 | P20: =SUM(G20,J20,M20) -> 0
B21: 7 | C21: LA GEORGINA RESORT | D21: NO RECORD SUBMITTED | M21: =SUM(K21:L21) -> 0 | N21: =SUM(E21,H21,K21) -> 0 | O21: =SUM(F21,I21,L21) -> 0 | P21: =SUM(G21,J21,M21) -> 0
B22: 8 | C22: LA PISCINA DI CONCEPCION RESORT | E22: 814 | F22: 807 | G22: 1620 | M22: =SUM(K22:L22) -> 0 | N22: =SUM(E22,H22,K22) -> 814 | O22: =SUM(F22,I22,L22) -> 807 | P22: =SUM(G22,J22,M22) -> 1620
B23: 9 | C23: MALABANAN SWIMMING POOL | D23: NO RECORD SUBMITTED | M23: =SUM(K23:L23) -> 0 | N23: =SUM(E23,H23,K23) -> 0 | O23: =SUM(F23,I23,L23) -> 0 | P23: =SUM(G23,J23,M23) -> 0
B24: 10 | C24: MY PLACE RESORT & PAVILLION | G24: 168 | M24: =SUM(K24:L24) -> 0 | N24: =SUM(E24,H24,K24) -> 0 | O24: =SUM(F24,I24,L24) -> 0 | P24: =SUM(G24,J24,M24) -> 168
B25: 11 | C25: VADZ CASTILLO RESIDENCE | D25: NO RECORD SUBMITTED | M25: =SUM(K25:L25) -> 0 | N25: =SUM(E25,H25,K25) -> 0 | O25: =SUM(F25,I25,L25) -> 0 | P25: =SUM(G25,J25,M25) -> 0
B26: 12 | C26: VIKTORIA'S GARDEN RESORT | E26: 166 | F26: 99 | G26: 260 | M26: =SUM(K26:L26) -> 0 | N26: =SUM(E26,H26,K26) -> 166 | O26: =SUM(F26,I26,L26) -> 99 | P26: =SUM(G26,J26,M26) -> 260
B27: 13 | C27: VILLA BEADOY RESORT & PAVILLION | E27: 296 | F27: 329 | G27: 625 | M27: =SUM(K27:L27) -> 0 | N27: =SUM(E27,H27,K27) -> 296 | O27: =SUM(F27,I27,L27) -> 329 | P27: =SUM(G27,J27,M27) -> 625
B28: 14 | C28: VILLA SCARLET GARDEN RESORT | E28: 47 | F28: 35 | G28: 82 | M28: =SUM(K28:L28) -> 0 | N28: =SUM(E28,H28,K28) -> 47 | O28: =SUM(F28,I28,L28) -> 35 | P28: =SUM(G28,J28,M28) -> 82
M29: =SUM(K29:L29) -> 0 | N29: =SUM(E29,H29,K29) -> 0 | O29: =SUM(F29,I29,L29) -> 0 | P29: =SUM(G29,J29,M29) -> 0
C30: TOURIST ATTRACTIONS
B31: 1 | C31: ATHENA RIVER RESORT | E31: 109 | F31: 47 | G31: =SUM(E31:F31) -> 156 | M31: =SUM(K31:L31) -> 0 | N31: =SUM(E31,H31,K31) -> 109 | O31: =SUM(F31,I31,L31) -> 47 | P31: =SUM(G31,J31,M31) -> 156
B32: 2 | C32: BALAYAN BAYWALK | G32: 8700 | M32: =SUM(K32:L32) -> 0 | N32: =SUM(E32,H32,K32) -> 0 | O32: =SUM(F32,I32,L32) -> 0 | P32: =SUM(G32,J32,M32) -> 8700
B33: 3 | C33: EL SENOR TRES CAIDAS CHAPEL | G33: 1480 | M33: =SUM(K33:L33) -> 0 | N33: =SUM(E33,H33,K33) -> 0 | O33: =SUM(F33,I33,L33) -> 0 | P33: =SUM(G33,J33,M33) -> 1480
B34: 4 | C34: IMMACULATE CONCEPTION PARISH | G34: 1456 | M34: =SUM(K34:L34) -> 0 | N34: =SUM(E34,H34,K34) -> 0 | O34: =SUM(F34,I34,L34) -> 0 | P34: =SUM(G34,J34,M34) -> 1456
B35: 5 | C35: MAGSINO CHOKDEE ECOCARE FARM | E35: 55 | F35: 67 | G35: 122 | M35: =SUM(K35:L35) -> 0 | N35: =SUM(E35,H35,K35) -> 55 | O35: =SUM(F35,I35,L35) -> 67 | P35: =SUM(G35,J35,M35) -> 122
B36: 6 | C36: MOLINO NATURE PARK | G36: 2980 | M36: =SUM(K36:L36) -> 0 | N36: =SUM(E36,H36,K36) -> 0 | O36: =SUM(F36,I36,L36) -> 0 | P36: =SUM(G36,J36,M36) -> 2980
C37: DIVISION MEET (FEB 12-16) | G37: 6789 | M37: =SUM(K37:L37) -> 0 | N37: =SUM(E37,H37,K37) -> 0 | O37: =SUM(F37,I37,L37) -> 0 | P37: =SUM(G37,J37,M37) -> 6789
B38: Total of this Month **** | E38: =SUM(E15:E37) -> 1699 | F38: =SUM(F15:F37) -> 1517 | G38: =SUM(G15:G37) -> 25630 | H38: =SUM(H15:H37) -> 0 | I38: =SUM(I15:I37) -> 0 | J38: =SUM(J15:J37) -> 0 | K38: =SUM(K15:K37) -> 0 | L38: =SUM(L15:L37) -> 0 | ... P38: =SUM(P15:P37) -> 25630
B39: Note: *Total number must be recorded, ** Sex & ***Residence entries are optional. Total number of this month must be reported.
B40: OVERNIGHT ARRIVALS
B41: Date | D41: 45689
C42: Accommodation Establishment | D42: Attraction Code | E42: (5) Number of Guests Check IN (unit: visitors) | F42: (6) Number of Guests staying over-night (Guest Nights) | G42: (7) Number of Rooms Occupied by Guests (unit: rooms) | H42: Average Guest/Night | I42: Average Room Occupancy Rate
B45: 1 | C45: ALVEZ LODGE & RESTAURANT | F45: 814 | G45: 407
...

Sheet MARCH 2025
B1: Tourism Attraction Visitor Record | P1: (VAR 1)
B2: ( This recording form can be used instead of just counting the visitors )
F4: Month/Year: | H4: 45717
F5: Name of City/Municipality: | H5: BALAYAN, BATANGAS
F6: Name of attraction/ Spot:
E8: Type of Tourism Attraction:
B10: DAYTOUR ARRIVALS
B11: Date | E11: *** Place of Residence | N11: * Grand Total Number of Visitors
C12: Accommodation Establishment | E12: Philippines | K12: Foreign Country Residence
E13: This province | H13: Other Province
D14: Attraction Code | E14: Male | F14: Female | G14: Total | H14: Male | I14: Female | J14: Total | K14: Male | L14: Female | M14: Total | N14: Male | O14: Female | P14: Total
B15: 1 | C15: AURORA RESORT | D15: NO RECORD SUBMITTED | G15: =SUM(E15:F15) -> 0 | J15: =SUM(H15:I15) -> 0 | M15: =SUM(K15:L15) -> 0 | N15: =SUM(E15,H15,K15) -> 0 | O15: =SUM(F15,I15,L15) -> 0 | P15: =SUM(G15,J15,M15) -> 0
B16: 2 | C16: ALTINA BEACH HOUSE | D16: NO RECORD SUBMITTED | G16: =SUM(E16:F16) -> 0 | J16: =SUM(H16:I16) -> 0 | M16: =SUM(K16:L16) -> 0 | N16: =SUM(E16,H16,K16) -> 0 | O16: =SUM(F16,I16,L16) -> 0 | P16: =SUM(G16,J16,M16) -> 0
B17: 3 | C17: CHRISOVA RESORT | E17: 33 | F17: 42 | G17: =SUM(E17:F17) -> 75 | J17: =SUM(H17:I17) -> 0 | M17: =SUM(K17:L17) -> 0 | N17: =SUM(E17,H17,K17) -> 33 | O17: =SUM(F17,I17,L17) -> 42 | P17: =SUM(G17,J17,M17) -> 75
B18: 4 | C18: DARLING ANGEL RESORT | E18: 268 | F18: 216 | G18: =SUM(E18:F18) -> 484 | J18: =SUM(H18:I18) -> 0 | M18: 0 | N18: 265 | O18: 279 | P18: =SUM(G18,J18,M18) -> 484
B19: 5 | C19: EASTERN STAR RESORT & INNS INC | E19: 175 | F19: 181 | G19: =SUM(E19:F19) -> 356 | H19: 400 | I19: 600 | J19: 1000 | M19: 0 | N19: 575 | O19: 781 | P19: =SUM(G19,J19,M19) -> 1356
B20: 6 | C20: KING & QUEEN RESORT | D20: NO RECORD SUBMITTED | G20: =SUM(E20:F20) -> 0 | J20: =SUM(H20:I20) -> 0 | M20: =SUM(K20:L20) -> 0 | N20: =SUM(E20,H20,K20) -> 0 | O20: =SUM(F20,I20,L20) -> 0 | P20: =SUM(G20,J20,M20) -> 0
B21: 7 | C21: LA GEORGINA RESORT | D21: NO RECORD SUBMITTED | G21: =SUM(E21:F21) -> 0 | J21: =SUM(H21:I21) -> 0 | M21: =SUM(K21:L21) -> 0 | N21: =SUM(E21,H21,K21) -> 0 | O21: =SUM(F21,I21,L21) -> 0 | P21: =SUM(G21,J21,M21) -> 0
B22: 8 | C22: LA PISCINA DI CONCEPCION RESORT | E22: 1178 | F22: 1159 | G22: =SUM(E22:F22) -> 2337 | J22: =SUM(H22:I22) -> 0 | M22: =SUM(K22:L22) -> 0 | N22: =SUM(E22,H22,K22) -> 1178 | O22: =SUM(F22,I22,L22) -> 1159 | P22: =SUM(G22,J22,M22) -> 2337
B23: 9 | C23: MALABANAN SWIMMING POOL | D23: NO RECORD SUBMITTED | G23: =SUM(E23:F23) -> 0 | J23: =SUM(H23:I23) -> 0 | M23: =SUM(K23:L23) -> 0 | N23: =SUM(E23,H23,K23) -> 0 | O23: =SUM(F23,I23,L23) -> 0 | P23: =SUM(G23,J23,M23) -> 0
B24: 10 | C24: MY PLACE RESORT & PAVILLION | G24: 398 | J24: =SUM(H24:I24) -> 0 | M24: =SUM(K24:L24) -> 0 | N24: =SUM(E24,H24,K24) -> 0 | O24: =SUM(F24,I24,L24) -> 0 | P24: =SUM(G24,J24,M24) -> 398
B25: 11 | C25: VADZ CASTILLO RESIDENCE | E25: 42 | F25: 41 | G25: =SUM(E25:F25) -> 83 | J25: =SUM(H25:I25) -> 0 | M25: =SUM(K25:L25) -> 0 | N25: =SUM(E25,H25,K25) -> 42 | O25: =SUM(F25,I25,L25) -> 41 | P25: =SUM(G25,J25,M25) -> 83
B26: 12 | C26: VIKTORIA'S GARDEN RESORT | E26: 629 | F26: 485 | G26: =SUM(E26:F26) -> 1114 | J26: =SUM(H26:I26) -> 0 | M26: =SUM(K26:L26) -> 0 | N26: =SUM(E26,H26,K26) -> 629 | O26: =SUM(F26,I26,L26) -> 485 | P26: =SUM(G26,J26,M26) -> 1114
B27: 13 | C27: VILLA BEADOY RESORT & PAVILLION | E27: 430 | F27: 482 | G27: =SUM(E27:F27) -> 912 | J27: =SUM(H27:I27) -> 0 | M27: =SUM(K27:L27) -> 0 | N27: =SUM(E27,H27,K27) -> 430 | O27: =SUM(F27,I27,L27) -> 482 | P27: =SUM(G27,J27,M27) -> 912
B28: 14 | C28: VILLA SCARLET GARDEN RESORT | E28: 66 | F28: 55 | G28: =SUM(E28:F28) -> 121 | J28: =SUM(H28:I28) -> 0 | M28: =SUM(K28:L28) -> 0 | N28: =SUM(E28,H28,K28) -> 66 | O28: =SUM(F28,I28,L28) -> 55 | P28: =SUM(G28,J28,M28) -> 121
C30: TOURIST ATTRACTIONS
B31: 1 | C31: ATHENA RIVER RESORT | E31: 352 | F31: 245 | G31: 597 | J31: =SUM(H31:I31) -> 0 | M31: =SUM(K31:L31) -> 0 | N31: =SUM(E31,H31,K31) -> 352 | O31: =SUM(F31,I31,L31) -> 245 | P31: =SUM(G31,J31,M31) -> 597
B32: 2 | C32: BALAYAN BAYWALK | G32: 19507 | J32: =SUM(H32:I32) -> 0 | M32: =SUM(K32:L32) -> 0 | N32: =SUM(E32,H32,K32) -> 0 | O32: =SUM(F32,I32,L32) -> 0 | P32: =SUM(G32,J32,M32) -> 19507
B33: 3 | C33: EL SENOR TRES CAIDAS CHAPEL | G33: 31976 | J33: =SUM(H33:I33) -> 0 | M33: =SUM(K33:L33) -> 0 | N33: =SUM(E33,H33,K33) -> 0 | O33: =SUM(F33,I33,L33) -> 0 | P33: =SUM(G33,J33,M33) -> 31976
B34: 4 | C34: IMMACULATE CONCEPTION PARISH | G34: 22764 | J34: =SUM(H34:I34) -> 0 | M34: =SUM(K34:L34) -> 0 | N34: =SUM(E34,H34,K34) -> 0 | O34: =SUM(F34,I34,L34) -> 0 | P34: =SUM(G34,J34,M34) -> 22764
B35: 5 | C35: MAGSINO CHOKDEE ECOCARE FARM | E35: 143 | F35: 110 | G35: =SUM(E35:F35) -> 253 | J35: =SUM(H35:I35) -> 0 | M35: =SUM(K35:L35) -> 0 | N35: =SUM(E35,H35,K35) -> 143 | O35: =SUM(F35,I35,L35) -> 110 | P35: =SUM(G35,J35,M35) -> 253
B36: 6 | C36: MOLINO NATURE PARK | G36: 3430 | P36: =SUM(G36,J36,M36) -> 3430
C37: EVENTS | G37: =SUM(E37:F37) -> 0 | J37: =SUM(H37:I37) -> 0 | M37: =SUM(K37:L37) -> 0 | N37: =SUM(E37,H37,K37) -> 0 | O37: =SUM(F37,I37,L37) -> 0 | P37: =SUM(G37,J37,M37) -> 0
B38: Total of this Month **** | E38: =SUM(E15:E37) -> 3316 | F38: =SUM(F15:F37) -> 3016 | G38: =SUM(G15:G37) -> 84407 | H38: =SUM(H15:H37) -> 400 | I38: =SUM(I15:I37) -> 600 | J38: =SUM(J15:J37) -> 1000 | K38: =SUM(K15:K37) -> 0 | L38: =SUM(L15:L37) -> 0 | ... P38: =SUM(P15:P37) -> 85407
B39: Note: *Total number must be recorded, ** Sex & ***Residence entries are optional. Total number of this month must be reported.
B40: OVERNIGHT ARRIVALS
B41: Date | D41: 45717
C42: Accommodation Establishment | D42: Attraction Code | E42: (5) Number of Guests Check IN (unit: visitors) | F42: (6) Number of Guests staying over-night (Guest Nights) | G42: (7) Number of Rooms Occupied by Guests (unit: rooms) | H42: Average Guest/Night | I42: Average Room Occupancy Rate
B45: 1 | C45: ALVEZ LODGE & RESTAURANT | F45: 842 | G45: 421
B46: 2 | C46: EASTERN STAR RESORT & INNS INC | E46: 116 | F46: 317 | G46: 184
...

Sheet APRIL 2025
B1: Tourism Attraction Visitor Record | P1: (VAR 1)
B2: ( This recording form can be used instead of just counting the visitors )
F4: Month/Year: | H4: 45748
F5: Name of City/Municipality: | H5: BALAYAN, BATANGAS
F6: Name of attraction/ Spot:
E8: Type of Tourism Attraction:
B10: DAYTOUR ARRIVALS
B11: Date | E11: *** Place of Residence | N11: * Grand Total Number of Visitors
C12: Accommodation Establishment | E12: Philippines | K12: Foreign Country Residence
H13: Other Province
D14: Attraction Code | E14: Male | F14: Female | G14: Total | H14: Male | I14: Female | J14: Total | K14: Male | L14: Female | M14: Total | N14: Male | O14: Female | P14: Total
B15: 1 | C15: AURORA RESORT | D15: NO RECORD SUBMITTED | G15: =SUM(E15:F15) -> 0 | J15: =SUM(H15:I15) -> 0 | M15: =SUM(K15:L15) -> 0 | N15: =SUM(E15,H15,K15) -> 0 | O15: =SUM(F15,I15,L15) -> 0 | P15: =SUM(G15,J15,M15) -> 0
B16: 2 | C16: ALTINA BEACH HOUSE | D16: NO RECORD SUBMITTED | G16: =SUM(E16:F16) -> 0 | J16: =SUM(H16:I16) -> 0 | M16: =SUM(K16:L16) -> 0 | N16: =SUM(E16,H16,K16) -> 0 | O16: =SUM(F16,I16,L16) -> 0 | P16: =SUM(G16,J16,M16) -> 0
B17: 3 | C17: CHRISOVA RESORT | E17: 528 | F17: 570 | G17: =SUM(E17:F17) -> 1098 | J17: =SUM(H17:I17) -> 0 | M17: =SUM(K17:L17) -> 0 | N17: =SUM(E17,H17,K17) -> 528 | O17: =SUM(F17,I17,L17) -> 570 | P17: =SUM(G17,J17,M17) -> 1098
B18: 4 | C18: DARLING ANGEL RESORT | E18: 571 | F18: 430 | G18: =SUM(E18:F18) -> 1001 | J18: =SUM(H18:I18) -> 0 | M18: =SUM(K18:L18) -> 0 | N18: =SUM(E18,H18,K18) -> 571 | O18: =SUM(F18,I18,L18) -> 430 | P18: =SUM(G18,J18,M18) -> 1001
B19: 5 | C19: EASTERN STAR RESORT & INNS INC | E19: 83 | F19: 107 | G19: =SUM(E19:F19) -> 190 | J19: 0 | M19: =SUM(K19:L19) -> 0 | N19: =SUM(E19,H19,K19) -> 83 | O19: =SUM(F19,I19,L19) -> 107 | P19: =SUM(G19,J19,M19) -> 190
B20: 6 | C20: KING & QUEEN RESORT | D20: NO RECORD SUBMITTED | G20: =SUM(E20:F20) -> 0 | J20: =SUM(H20:I20) -> 0 | M20: =SUM(K20:L20) -> 0 | N20: =SUM(E20,H20,K20) -> 0 | O20: =SUM(F20,I20,L20) -> 0 | P20: =SUM(G20,J20,M20) -> 0
B21: 7 | C21: LA GEORGINA RESORT | D21: NO RECORD SUBMITTED | G21: =SUM(E21:F21) -> 0 | J21: =SUM(H21:I21) -> 0 | M21: =SUM(K21:L21) -> 0 | N21: =SUM(E21,H21,K21) -> 0 | O21: =SUM(F21,I21,L21) -> 0 | P21: =SUM(G21,J21,M21) -> 0
B22: 8 | C22: LA PISCINA DI CONCEPCION RESORT | E22: 2153 | F22: 2184 | G22: =SUM(E22:F22) -> 4337 | J22: =SUM(H22:I22) -> 0 | M22: =SUM(K22:L22) -> 0 | N22: =SUM(E22,H22,K22) -> 2153 | O22: =SUM(F22,I22,L22) -> 2184 | P22: =SUM(G22,J22,M22) -> 4337
B23: 9 | C23: MALABANAN SWIMMING POOL | D23: NO RECORD SUBMITTED | G23: =SUM(E23:F23) -> 0 | J23: =SUM(H23:I23) -> 0 | M23: =SUM(K23:L23) -> 0 | N23: =SUM(E23,H23,K23) -> 0 | O23: =SUM(F23,I23,L23) -> 0 | P23: =SUM(G23,J23,M23) -> 0
B24: 10 | C24: MY PLACE RESORT & PAVILLION | G24: 168 | J24: =SUM(H24:I24) -> 0 | M24: =SUM(K24:L24) -> 0 | N24: =SUM(E24,H24,K24) -> 0 | O24: =SUM(F24,I24,L24) -> 0 | P24: =SUM(G24,J24,M24) -> 168
B25: 11 | C25: VADZ CASTILLO RESIDENCE | E25: 121 | F25: 130 | G25: =SUM(E25:F25) -> 251 | J25: =SUM(H25:I25) -> 0 | M25: =SUM(K25:L25) -> 0 | N25: =SUM(E25,H25,K25) -> 121 | O25: =SUM(F25,I25,L25) -> 130 | P25: =SUM(G25,J25,M25) -> 251
B26: 12 | C26: VIKTORIA'S GARDEN RESORT | E26: 175 | F26: 167 | G26: =SUM(E26:F26) -> 342 | J26: =SUM(H26:I26) -> 0 | M26: =SUM(K26:L26) -> 0 | N26: =SUM(E26,H26,K26) -> 175 | O26: =SUM(F26,I26,L26) -> 167 | P26: =SUM(G26,J26,M26) -> 342
B27: 13 | C27: VILLA BEADOY RESORT & PAVILLION | E27: 419 | F27: 471 | G27: =SUM(E27:F27) -> 890 | J27: =SUM(H27:I27) -> 0 | M27: =SUM(K27:L27) -> 0 | N27: =SUM(E27,H27,K27) -> 419 | O27: =SUM(F27,I27,L27) -> 471 | P27: =SUM(G27,J27,M27) -> 890
B28: 14 | C28: VILLA SCARLET GARDEN RESORT | E28: 30 | F28: 32 | G28: =SUM(E28:F28) -> 62 | J28: =SUM(H28:I28) -> 0 | M28: =SUM(K28:L28) -> 0 | N28: =SUM(E28,H28,K28) -> 30 | O28: =SUM(F28,I28,L28) -> 32 | P28: =SUM(G28,J28,M28) -> 62
C30: TOURIST ATTRACTIONS
B31: 1 | C31: ATHENA RIVER RESORT | E31: 898 | F31: 599 | G31: =SUM(E31:F31) -> 1497 | J31: =SUM(H31:I31) -> 0 | M31: =SUM(K31:L31) -> 0 | N31: =SUM(E31,H31,K31) -> 898 | O31: =SUM(F31,I31,L31) -> 599 | P31: =SUM(G31,J31,M31) -> 1497
B32: 2 | C32: BALAYAN BAYWALK | G32: 18081 | J32: =SUM(H32:I32) -> 0 | M32: =SUM(K32:L32) -> 0 | N32: =SUM(E32,H32,K32) -> 0 | O32: =SUM(F32,I32,L32) -> 0 | P32: =SUM(G32,J32,M32) -> 18081
B33: 3 | C33: EL SENOR TRES CAIDAS CHAPEL | G33: 1740 | J33: =SUM(H33:I33) -> 0 | M33: =SUM(K33:L33) -> 0 | N33: =SUM(E33,H33,K33) -> 0 | O33: =SUM(F33,I33,L33) -> 0 | P33: =SUM(G33,J33,M33) -> 1740
B34: 4 | C34: IMMACULATE CONCEPTION PARISH | G34: 11440 | J34: =SUM(H34:I34) -> 0 | M34: =SUM(K34:L34) -> 0 | N34: =SUM(E34,H34,K34) -> 0 | O34: =SUM(F34,I34,L34) -> 0 | P34: =SUM(G34,J34,M34) -> 11440
B35: 5 | C35: MAGSINO CHOKDEE ECOCARE FARM | E35: 95 | F35: 101 | G35: 196 | J35: =SUM(H35:I35) -> 0 | M35: =SUM(K35:L35) -> 0 | N35: =SUM(E35,H35,K35) -> 95 | O35: =SUM(F35,I35,L35) -> 101 | P35: =SUM(G35,J35,M35) -> 196
B36: 6 | C36: MOLINO NATURE PARK | G36: 3120 | P36: =SUM(G36,J36,M36) -> 3120
C37: EVENTS | G37: =SUM(E37:F37) -> 0 | J37: =SUM(H37:I37) -> 0 | M37: =SUM(K37:L37) -> 0 | N37: =SUM(E37,H37,K37) -> 0 | O37: =SUM(F37,I37,L37) -> 0 | P37: =SUM(G37,J37,M37) -> 0
B38: Total of this Month **** | E38: =SUM(E15:E37) -> 5073 | F38: =SUM(F15:F37) -> 4791 | G38: =SUM(G15:G37) -> 44413 | H38: =SUM(H15:H37) -> 0 | I38: =SUM(I15:I37) -> 0 | J38: =SUM(J15:J37) -> 0 | K38: =SUM(K15:K37) -> 0 | L38: =SUM(L15:L37) -> 0 | ... P38: =SUM(P15:P37) -> 44413
B39: Note: *Total number must be recorded, ** Sex & ***Residence entries are optional. Total number of this month must be reported.
B40: OVERNIGHT ARRIVALS
B41: Date | D41: 45748
C42: Accommodation Establishment | D42: Attraction Code | E42: (5) Number of Guests Check IN (unit: visitors) | F42: (6) Number of Guests staying over-night (Guest Nights) | G42: (7) Number of Rooms Occupied by Guests (unit: rooms) | H42: Average Guest/Night | I42: Average Room Occupancy Rate
B45: 1 | C45: ALVEZ LODGE & RESTAURANT | E45: 754 | F45: 754 | G45: 374
B46: 2 | C46: EASTERN STAR RESORT & INNS INC | E46: 16 | F46: 57 | G46: 57
...

Sheet MAY 2025
B1: Tourism Attraction Visitor Record | P1: (VAR 1)
B2: ( This recording form can be used instead of just counting the visitors )
F4: Month/Year: | H4: 45778
F5: Name of City/Municipality: | H5: BALAYAN, BATANGAS
F6: Name of attraction/ Spot:
E8: Type of Tourism Attraction:
B10: DAYTOUR ARRIVALS
B11: Date | E11: *** Place of Residence | N11: * Grand Total Number of Visitors
C12: Accommodation Establishment | E12: Philippines | K12: Foreign Country Residence
E13: This province | H13: Other Province
D14: Attraction Code | E14: Male | F14: Female | G14: Total | H14: Male | I14: Female | J14: Total | K14: Male | L14: Female | M14: Total | N14: Male | O14: Female | P14: Total
B15: 1 | C15: AURORA RESORT | D15: NO RECORD SUBMITTED | G15: =SUM(E15:F15) -> 0 | J15: =SUM(H15:I15) -> 0 | M15: =SUM(K15:L15) -> 0 | N15: =SUM(E15,H15,K15) -> 0 | O15: =SUM(F15,I15,L15) -> 0 | P15: =SUM(G15,J15,M15) -> 0
B16: 2 | C16: ALTINA BEACH HOUSE | D16: NO RECORD SUBMITTED | G16: =SUM(E16:F16) -> 0 | J16: =SUM(H16:I16) -> 0 | M16: =SUM(K16:L16) -> 0 | N16: =SUM(E16,H16,K16) -> 0 | O16: =SUM(F16,I16,L16) -> 0 | P16: =SUM(G16,J16,M16) -> 0
B17: 3 | C17: CHRISOVA RESORT | E17: 239 | F17: 270 | G17: =SUM(E17:F17) -> 509 | J17: =SUM(H17:I17) -> 0 | M17: =SUM(K17:L17) -> 0 | N17: =SUM(E17,H17,K17) -> 239 | O17: =SUM(F17,I17,L17) -> 270 | P17: =SUM(G17,J17,M17) -> 509
B18: 4 | C18: DARLING ANGEL RESORT | E18: 503 | F18: 448 | G18: =SUM(E18:F18) -> 951 | H18: 10 | I18: 12 | J18: =SUM(H18:I18) -> 22 | M18: =SUM(K18:L18) -> 0 | N18: =SUM(E18,H18,K18) -> 513 | O18: =SUM(F18,I18,L18) -> 460 | P18: =SUM(G18,J18,M18) -> 973
B19: 5 | C19: EASTERN STAR RESORT & INNS INC | E19: 455 | F19: 449 | G19: 904 | J19: 0 | M19: =SUM(K19:L19) -> 0 | N19: =SUM(E19,H19,K19) -> 455 | O19: =SUM(F19,I19,L19) -> 449 | P19: =SUM(G19,J19,M19) -> 904
B20: 6 | C20: KING & QUEEN RESORT | D20: NO RECORD SUBMITTED | G20: =SUM(E20:F20) -> 0 | J20: =SUM(H20:I20) -> 0 | M20: =SUM(K20:L20) -> 0 | N20: =SUM(E20,H20,K20) -> 0 | O20: =SUM(F20,I20,L20) -> 0 | P20: =SUM(G20,J20,M20) -> 0
B21: 7 | C21: LA GEORGINA RESORT | D21: NO RECORD SUBMITTED | G21: =SUM(E21:F21) -> 0 | J21: =SUM(H21:I21) -> 0 | M21: =SUM(K21:L21) -> 0 | N21: =SUM(E21,H21,K21) -> 0 | O21: =SUM(F21,I21,L21) -> 0 | P21: =SUM(G21,J21,M21) -> 0
B22: 8 | C22: LA PISCINA DI CONCEPCION RESORT | E22: 1407 | F22: 1454 | G22: =SUM(E22:F22) -> 2861 | J22: =SUM(H22:I22) -> 0 | M22: =SUM(K22:L22) -> 0 | N22: =SUM(E22,H22,K22) -> 1407 | O22: =SUM(F22,I22,L22) -> 1454 | P22: =SUM(G22,J22,M22) -> 2861
B23: 9 | C23: MALABANAN SWIMMING POOL | D23: NO RECORD SUBMITTED | G23: =SUM(E23:F23) -> 0 | J23: =SUM(H23:I23) -> 0 | M23: =SUM(K23:L23) -> 0 | N23: =SUM(E23,H23,K23) -> 0 | O23: =SUM(F23,I23,L23) -> 0 | P23: =SUM(G23,J23,M23) -> 0
B24: 10 | C24: MY PLACE RESORT & PAVILLION | G24: 235 | J24: =SUM(H24:I24) -> 0 | M24: =SUM(K24:L24) -> 0 | N24: =SUM(E24,H24,K24) -> 0 | O24: =SUM(F24,I24,L24) -> 0 | P24: =SUM(G24,J24,M24) -> 235
B25: 11 | C25: VADZ CASTILLO RESIDENCE | E25: 67 | F25: 80 | G25: =SUM(E25:F25) -> 147 | J25: =SUM(H25:I25) -> 0 | M25: =SUM(K25:L25) -> 0 | N25: =SUM(E25,H25,K25) -> 67 | O25: =SUM(F25,I25,L25) -> 80 | P25: =SUM(G25,J25,M25) -> 147
B26: 12 | C26: VIKTORIA'S GARDEN RESORT | E26: 192 | F26: 174 | G26: =SUM(E26:F26) -> 366 | J26: =SUM(H26:I26) -> 0 | M26: =SUM(K26:L26) -> 0 | N26: =SUM(E26,H26,K26) -> 192 | O26: =SUM(F26,I26,L26) -> 174 | P26: =SUM(G26,J26,M26) -> 366
B27: 13 | C27: VILLA BEADOY RESORT & PAVILLION | E27: 326 | F27: 371 | G27: =SUM(E27:F27) -> 697 | J27: =SUM(H27:I27) -> 0 | M27: =SUM(K27:L27) -> 0 | N27: =SUM(E27,H27,K27) -> 326 | O27: =SUM(F27,I27,L27) -> 371 | P27: =SUM(G27,J27,M27) -> 697
B28: 14 | C28: VILLA SCARLET GARDEN RESORT | E28: 27 | F28: 48 | G28: =SUM(E28:F28) -> 75 | J28: =SUM(H28:I28) -> 0 | M28: =SUM(K28:L28) -> 0 | N28: =SUM(E28,H28,K28) -> 27 | O28: =SUM(F28,I28,L28) -> 48 | P28: =SUM(G28,J28,M28) -> 75
C30: TOURIST ATTRACTIONS
B31: 1 | C31: ATHENA RIVER RESORT | D31: NO RECORD SUBMITTED | G31: =SUM(E31:F31) -> 0 | J31: =SUM(H31:I31) -> 0 | M31: =SUM(K31:L31) -> 0 | N31: =SUM(E31,H31,K31) -> 0 | O31: =SUM(F31,I31,L31) -> 0 | P31: =SUM(G31,J31,M31) -> 0
B32: 2 | C32: BALAYAN BAYWALK | G32: 15476 | J32: =SUM(H32:I32) -> 0 | M32: =SUM(K32:L32) -> 0 | N32: =SUM(E32,H32,K32) -> 0 | O32: =SUM(F32,I32,L32) -> 0 | P32: =SUM(G32,J32,M32) -> 15476
B33: 3 | C33: EL SENOR TRES CAIDAS CHAPEL | G33: 3780 | J33: =SUM(H33:I33) -> 0 | M33: =SUM(K33:L33) -> 0 | N33: =SUM(E33,H33,K33) -> 0 | O33: =SUM(F33,I33,L33) -> 0 | P33: =SUM(G33,J33,M33) -> 3780
B34: 4 | C34: IMMACULATE CONCEPTION PARISH | G34: 11040 | J34: =SUM(H34:I34) -> 0 | M34: =SUM(K34:L34) -> 0 | N34: =SUM(E34,H34,K34) -> 0 | O34: =SUM(F34,I34,L34) -> 0 | P34: =SUM(G34,J34,M34) -> 11040
B35: 5 | C35: MAGSINO CHOKDEE ECOCARE FARM | E35: 44 | F35: 63 | G35: 107 | J35: =SUM(H35:I35) -> 0 | M35: =SUM(K35:L35) -> 0 | N35: =SUM(E35,H35,K35) -> 44 | O35: =SUM(F35,I35,L35) -> 63 | P35: =SUM(G35,J35,M35) -> 107
B36: 6 | C36: MOLINO NATURE PARK | G36: 2813 | P36: =SUM(G36,J36,M36) -> 2813
C37: EVENTS | G37: =SUM(E37:F37) -> 0 | J37: =SUM(H37:I37) -> 0 | M37: =SUM(K37:L37) -> 0 | N37: =SUM(E37,H37,K37) -> 0 | O37: =SUM(F37,I37,L37) -> 0 | P37: =SUM(G37,J37,M37) -> 0
B38: Total of this Month **** | E38: =SUM(E15:E37) -> 3260 | F38: =SUM(F15:F37) -> 3357 | G38: =SUM(G15:G37) -> 39961 | H38: =SUM(H15:H37) -> 10 | I38: =SUM(I15:I37) -> 12 | J38: =SUM(J15:J37) -> 22 | K38: =SUM(K15:K37) -> 0 | L38: =SUM(L15:L37) -> 0 | ... P38: =SUM(P15:P37) -> 39983
B39: Note: *Total number must be recorded, ** Sex & ***Residence entries are optional. Total number of this month must be reported.
B40: OVERNIGHT ARRIVALS
B41: Date | D41: 45778
C42: Accommodation Establishment | D42: Attraction Code | E42: (5) Number of Guests Check IN (unit: visitors) | F42: (6) Number of Guests staying over-night (Guest Nights) | G42: (7) Number of Rooms Occupied by Guests (unit: rooms) | H42: Average Guest/Night | I42: Average Room Occupancy Rate
B45: 1 | C45: ALVEZ LODGE & RESTAURANT | E45: 734 | F45: 734 | G45: 363
B46: 2 | C46: EASTERN STAR RESORT & INNS INC | E46: 54 | F46: 54 | G46: 26
...

Sheet JUNE 2025
B1: Tourism Attraction Visitor Record | P1: (VAR 1)
B2: ( This recording form can be used instead of just counting the visitors )
F4: Month/Year: | H4: 45809
F5: Name of City/Municipality: | H5: BALAYAN, BATANGAS
F6: Name of attraction/ Spot:
E8: Type of Tourism Attraction:
B10: DAYTOUR ARRIVALS
B11: Date | E11: *** Place of Residence | N11: * Grand Total Number of Visitors
C12: Accommodation Establishment | E12: Philippines | K12: Foreign Country Residence
E13: This province | H13: Other Province
D14: Attraction Code | E14: Male | F14: Female | G14: Total | H14: Male | I14: Female | J14: Total | K14: Male | L14: Female | M14: Total | N14: Male | O14: Female | P14: Total
B15: 1 | C15: AURORA RESORT | D15: NO RECORD SUBMITTED | G15: =SUM(E15:F15) -> 0 | J15: =SUM(H15:I15) -> 0 | M15: =SUM(K15:L15) -> 0 | N15: =SUM(E15,H15,K15) -> 0 | O15: =SUM(F15,I15,L15) -> 0 | P15: =SUM(G15,J15,M15) -> 0
B16: 2 | C16: ALTINA BEACH HOUSE | D16: NO RECORD SUBMITTED | G16: =SUM(E16:F16) -> 0 | J16: =SUM(H16:I16) -> 0 | M16: =SUM(K16:L16) -> 0 | N16: =SUM(E16,H16,K16) -> 0 | O16: =SUM(F16,I16,L16) -> 0 | P16: =SUM(G16,J16,M16) -> 0
B17: 3 | C17: CHRISOVA RESORT | E17: 106 | F17: 113 | G17: =SUM(E17:F17) -> 219 | J17: =SUM(H17:I17) -> 0 | M17: =SUM(K17:L17) -> 0 | N17: =SUM(E17,H17,K17) -> 106 | O17: =SUM(F17,I17,L17) -> 113 | P17: =SUM(G17,J17,M17) -> 219
B18: 4 | C18: DARLING ANGEL RESORT | E18: 354 | F18: 360 | G18: =SUM(E18:F18) -> 714 | H18: 7 | I18: 10 | J18: =SUM(H18:I18) -> 17 | M18: =SUM(K18:L18) -> 0 | N18: =SUM(E18,H18,K18) -> 361 | O18: =SUM(F18,I18,L18) -> 370 | P18: =SUM(G18,J18,M18) -> 731
B19: 5 | C19: EASTERN STAR RESORT & INNS INC | E19: 711 | F19: 712 | G19: 1423 | J19: 0 | M19: =SUM(K19:L19) -> 0 | N19: =SUM(E19,H19,K19) -> 711 | O19: =SUM(F19,I19,L19) -> 712 | P19: =SUM(G19,J19,M19) -> 1423
B20: 6 | C20: KING & QUEEN RESORT | D20: NO RECORD SUBMITTED | G20: =SUM(E20:F20) -> 0 | J20: =SUM(H20:I20) -> 0 | M20: =SUM(K20:L20) -> 0 | N20: =SUM(E20,H20,K20) -> 0 | O20: =SUM(F20,I20,L20) -> 0 | P20: =SUM(G20,J20,M20) -> 0
B21: 7 | C21: LA GEORGINA RESORT | D21: NO RECORD SUBMITTED | G21: =SUM(E21:F21) -> 0 | J21: =SUM(H21:I21) -> 0 | M21: =SUM(K21:L21) -> 0 | N21: =SUM(E21,H21,K21) -> 0 | O21: =SUM(F21,I21,L21) -> 0 | P21: =SUM(G21,J21,M21) -> 0
B22: 8 | C22: LA PISCINA DI CONCEPCION RESORT | E22: 2128 | F22: 2027 | G22: 4155 | J22: =SUM(H22:I22) -> 0 | M22: =SUM(K22:L22) -> 0 | N22: =SUM(E22,H22,K22) -> 2128 | O22: =SUM(F22,I22,L22) -> 2027 | P22: =SUM(G22,J22,M22) -> 4155
B23: 9 | C23: MALABANAN SWIMMING POOL | D23: NO RECORD SUBMITTED | G23: =SUM(E23:F23) -> 0 | J23: =SUM(H23:I23) -> 0 | M23: =SUM(K23:L23) -> 0 | N23: =SUM(E23,H23,K23) -> 0 | O23: =SUM(F23,I23,L23) -> 0 | P23: =SUM(G23,J23,M23) -> 0
B24: 10 | C24: MY PLACE RESORT & PAVILLION | G24: 590 | J24: =SUM(H24:I24) -> 0 | M24: =SUM(K24:L24) -> 0 | N24: =SUM(E24,H24,K24) -> 0 | O24: =SUM(F24,I24,L24) -> 0 | P24: =SUM(G24,J24,M24) -> 590
B25: 11 | C25: VADZ CASTILLO RESIDENCE | E25: 139 | F25: 144 | G25: =SUM(E25:F25) -> 283 | J25: =SUM(H25:I25) -> 0 | M25: =SUM(K25:L25) -> 0 | N25: =SUM(E25,H25,K25) -> 139 | O25: =SUM(F25,I25,L25) -> 144 | P25: =SUM(G25,J25,M25) -> 283
B26: 12 | C26: VIKTORIA'S GARDEN RESORT | E26: 151 | F26: 128 | G26: =SUM(E26:F26) -> 279 | J26: =SUM(H26:I26) -> 0 | M26: =SUM(K26:L26) -> 0 | N26: =SUM(E26,H26,K26) -> 151 | O26: =SUM(F26,I26,L26) -> 128 | P26: =SUM(G26,J26,M26) -> 279
B27: 13 | C27: VILLA BEADOY RESORT & PAVILLION | E27: 500 | F27: 524 | G27: =SUM(E27:F27) -> 1024 | I27: 20 | J27: =SUM(H27:I27) -> 20 | M27: =SUM(K27:L27) -> 0 | N27: =SUM(E27,H27,K27) -> 500 | O27: =SUM(F27,I27,L27) -> 544 | P27: =SUM(G27,J27,M27) -> 1044
B28: 14 | C28: VILLA SCARLET GARDEN RESORT | E28: 19 | F28: 9 | G28: =SUM(E28:F28) -> 28 | J28: =SUM(H28:I28) -> 0 | M28: =SUM(K28:L28) -> 0 | N28: =SUM(E28,H28,K28) -> 19 | O28: =SUM(F28,I28,L28) -> 9 | P28: =SUM(G28,J28,M28) -> 28
C30: TOURIST ATTRACTIONS
B31: 1 | C31: ATHENA RIVER RESORT | G31: =SUM(E31:F31) -> 0 | J31: =SUM(H31:I31) -> 0 | M31: =SUM(K31:L31) -> 0 | N31: =SUM(E31,H31,K31) -> 0 | O31: =SUM(F31,I31,L31) -> 0 | P31: =SUM(G31,J31,M31) -> 0
B32: 2 | C32: BALAYAN BAYWALK | G32: 20154 | J32: =SUM(H32:I32) -> 0 | M32: =SUM(K32:L32) -> 0 | N32: =SUM(E32,H32,K32) -> 0 | O32: =SUM(F32,I32,L32) -> 0 | P32: =SUM(G32,J32,M32) -> 20154
B33: 3 | C33: EL SENOR TRES CAIDAS CHAPEL | G33: 3720 | J33: =SUM(H33:I33) -> 0 | M33: =SUM(K33:L33) -> 0 | N33: =SUM(E33,H33,K33) -> 0 | O33: =SUM(F33,I33,L33) -> 0 | P33: =SUM(G33,J33,M33) -> 3720
B34: 4 | C34: IMMACULATE CONCEPTION PARISH | G34: 12030 | J34: =SUM(H34:I34) -> 0 | M34: =SUM(K34:L34) -> 0 | N34: =SUM(E34,H34,K34) -> 0 | O34: =SUM(F34,I34,L34) -> 0 | P34: =SUM(G34,J34,M34) -> 12030
B35: 5 | C35: MAGSINO CHOKDEE ECOCARE FARM | E35: 64 | F35: 78 | G35: 142 | J35: =SUM(H35:I35) -> 0 | M35: =SUM(K35:L35) -> 0 | N35: =SUM(E35,H35,K35) -> 64 | O35: =SUM(F35,I35,L35) -> 78 | P35: =SUM(G35,J35,M35) -> 142
B36: 6 | C36: MOLINO NATURE PARK | G36: 1453 | P36: =SUM(G36,J36,M36) -> 1453
C37: PARADA NG LECHON FESTIVAL | G37: 36759 | J37: =SUM(H37:I37) -> 0 | M37: =SUM(K37:L37) -> 0 | N37: =SUM(E37,H37,K37) -> 0 | O37: =SUM(F37,I37,L37) -> 0 | P37: =SUM(G37,J37,M37) -> 36759
B38: Total of this Month **** | E38: =SUM(E15:E37) -> 4172 | F38: =SUM(F15:F37) -> 4095 | G38: =SUM(G15:G37) -> 82973 | H38: =SUM(H15:H37) -> 7 | I38: =SUM(I15:I37) -> 30 | J38: =SUM(J15:J37) -> 37 | K38: =SUM(K15:K37) -> 0 | L38: =SUM(L15:L37) -> 0 | ... P38: =SUM(P15:P37) -> 83010
B39: Note: *Total number must be recorded, ** Sex & ***Residence entries are optional. Total number of this month must be reported.
B40: OVERNIGHT ARRIVALS
B41: Date | D41: 45809
C42: Accommodation Establishment | D42: Attraction Code | E42: (5) Number of Guests Check IN (unit: visitors) | F42: (6) Number of Guests staying over-night (Guest Nights) | G42: (7) Number of Rooms Occupied by Guests (unit: rooms) | H42: Average Guest/Night | I42: Average Room Occupancy Rate
B45: 1 | C45: ALVEZ LODGE & RESTAURANT | E45: 696 | F45: 696 | G45: 360
B46: 2 | C46: EASTERN STAR RESORT & INNS INC | E46: 193 | F46: 193 | G46: 76
...

Sheet JULY 2025
B1: Tourism Attraction Visitor Record | P1: (VAR 1)
B2: ( This recording form can be used instead of just counting the visitors )
F4: Month/Year: | H4: 45839
F5: Name of City/Municipality: | H5: BALAYAN, BATANGAS
F6: Name of attraction/ Spot:
E8: Type of Tourism Attraction:
B10: DAYTOUR ARRIVALS
B11: Date | E11: *** Place of Residence | N11: * Grand Total Number of Visitors
C12: Accommodation Establishment | E12: Philippines | K12: Foreign Country Residence
E13: This province | H13: Other Province
D14: Attraction Code | E14: Male | F14: Female | G14: Total | H14: Male | I14: Female | J14: Total | K14: Male | L14: Female | M14: Total | N14: Male | O14: Female | P14: Total
B15: 1 | C15: AURORA RESORT | D15: NO RECORD SUBMITTED | G15: =SUM(E15:F15) -> 0 | J15: =SUM(H15:I15) -> 0 | M15: =SUM(K15:L15) -> 0 | N15: =SUM(E15,H15,K15) -> 0 | O15: =SUM(F15,I15,L15) -> 0 | P15: =SUM(G15,J15,M15) -> 0
B16: 2 | C16: ALTINA BEACH HOUSE | D16: NO RECORD SUBMITTED | G16: =SUM(E16:F16) -> 0 | J16: =SUM(H16:I16) -> 0 | M16: =SUM(K16:L16) -> 0 | N16: =SUM(E16,H16,K16) -> 0 | O16: =SUM(F16,I16,L16) -> 0 | P16: =SUM(G16,J16,M16) -> 0
B17: 3 | C17: CHRISOVA RESORT | E17: 41 | F17: 32 | G17: 78 | J17: =SUM(H17:I17) -> 0 | M17: =SUM(K17:L17) -> 0 | N17: =SUM(E17,H17,K17) -> 41 | O17: 32 | P17: =SUM(G17,J17,M17) -> 78
B18: 4 | C18: DARLING ANGEL RESORT | E18: 113 | F18: 87 | G18: 200 | J18: =SUM(H18:I18) -> 0 | M18: =SUM(K18:L18) -> 0 | N18: =SUM(E18,H18,K18) -> 113 | O18: =SUM(F18,I18,L18) -> 87 | P18: =SUM(G18,J18,M18) -> 200
B19: 5 | C19: EASTERN STAR RESORT & INNS INC | G19: 380 | J19: 0 | M19: =SUM(K19:L19) -> 0 | N19: =SUM(E19,H19,K19) -> 0 | O19: =SUM(F19,I19,L19) -> 0 | P19: =SUM(G19,J19,M19) -> 380
B20: 6 | C20: KING & QUEEN RESORT | D20: NO RECORD SUBMITTED | G20: =SUM(E20:F20) -> 0 | J20: =SUM(H20:I20) -> 0 | M20: =SUM(K20:L20) -> 0 | N20: =SUM(E20,H20,K20) -> 0 | O20: =SUM(F20,I20,L20) -> 0 | P20: =SUM(G20,J20,M20) -> 0
B21: 7 | C21: LA GEORGINA RESORT | D21: NO RECORD SUBMITTED | G21: =SUM(E21:F21) -> 0 | J21: =SUM(H21:I21) -> 0 | M21: =SUM(K21:L21) -> 0 | N21: =SUM(E21,H21,K21) -> 0 | O21: =SUM(F21,I21,L21) -> 0 | P21: =SUM(G21,J21,M21) -> 0
B22: 8 | C22: LA PISCINA DI CONCEPCION RESORT | D22: NO RECORD SUBMITTED | G22: =SUM(E22:F22) -> 0 | J22: =SUM(H22:I22) -> 0 | M22: =SUM(K22:L22) -> 0 | N22: =SUM(E22,H22,K22) -> 0 | O22: =SUM(F22,I22,L22) -> 0 | P22: =SUM(G22,J22,M22) -> 0
B23: 9 | C23: MALABANAN SWIMMING POOL | D23: NO RECORD SUBMITTED | G23: =SUM(E23:F23) -> 0 | J23: =SUM(H23:I23) -> 0 | M23: =SUM(K23:L23) -> 0 | N23: =SUM(E23,H23,K23) -> 0 | O23: =SUM(F23,I23,L23) -> 0 | P23: =SUM(G23,J23,M23) -> 0
B24: 10 | C24: MY PLACE RESORT & PAVILLION | E24: 95 | F24: 119 | G24: =SUM(E24:F24) -> 214 | J24: =SUM(H24:I24) -> 0 | M24: =SUM(K24:L24) -> 0 | N24: =SUM(E24,H24,K24) -> 95 | O24: =SUM(F24,I24,L24) -> 119 | P24: =SUM(G24,J24,M24) -> 214
B25: 11 | C25: VADZ CASTILLO RESIDENCE | E25: 17 | F25: 32 | G25: 49 | J25: =SUM(H25:I25) -> 0 | M25: =SUM(K25:L25) -> 0 | N25: =SUM(E25,H25,K25) -> 17 | O25: =SUM(F25,I25,L25) -> 32 | P25: =SUM(G25,J25,M25) -> 49
B26: 12 | C26: VIKTORIA'S GARDEN RESORT | E26: 243 | F26: 158 | G26: =SUM(E26:F26) -> 401 | J26: =SUM(H26:I26) -> 0 | M26: =SUM(K26:L26) -> 0 | N26: =SUM(E26,H26,K26) -> 243 | O26: =SUM(F26,I26,L26) -> 158 | P26: =SUM(G26,J26,M26) -> 401
B27: 13 | C27: VILLA BEADOY RESORT & PAVILLION | E27: 430 | F27: 594 | G27: 1024 | J27: 0 | M27: =SUM(K27:L27) -> 0 | N27: =SUM(E27,H27,K27) -> 430 | O27: =SUM(F27,I27,L27) -> 594 | P27: =SUM(G27,J27,M27) -> 1024
B28: 14 | C28: VILLA SCARLET GARDEN RESORT | E28: 28 | F28: 21 | G28: 49 | J28: 0 | M28: =SUM(K28:L28) -> 0 | N28: =SUM(E28,H28,K28) -> 28 | O28: =SUM(F28,I28,L28) -> 21 | P28: =SUM(G28,J28,M28) -> 49
B29: 15 | C29: SOGGIORNS | E29: 31 | F29: 21 | G29: 52 | J29: 0 | M29: =SUM(K29:L29) -> 0 | N29: =SUM(E29,H29,K29) -> 31 | O29: =SUM(F29,I29,L29) -> 21 | P29: =SUM(G29,J29,M29) -> 52
C30: TOURIST ATTRACTIONS
B31: 1 | C31: ATHENA RIVER RESORT | D31: NO RECORD SUBMITTED | G31: =SUM(E31:F31) -> 0 | J31: =SUM(H31:I31) -> 0 | M31: =SUM(K31:L31) -> 0 | N31: =SUM(E31,H31,K31) -> 0 | O31: =SUM(F31,I31,L31) -> 0 | P31: =SUM(G31,J31,M31) -> 0
B32: 2 | C32: BALAYAN BAYWALK | G32: 14645 | J32: =SUM(H32:I32) -> 0 | M32: =SUM(K32:L32) -> 0 | N32: =SUM(E32,H32,K32) -> 0 | O32: =SUM(F32,I32,L32) -> 0 | P32: =SUM(G32,J32,M32) -> 14645
B33: 3 | C33: EL SENOR TRES CAIDAS CHAPEL | G33: 1788 | J33: =SUM(H33:I33) -> 0 | M33: =SUM(K33:L33) -> 0 | N33: =SUM(E33,H33,K33) -> 0 | O33: =SUM(F33,I33,L33) -> 0 | P33: =SUM(G33,J33,M33) -> 1788
B34: 4 | C34: IMMACULATE CONCEPTION PARISH | G34: 10314 | J34: =SUM(H34:I34) -> 0 | M34: =SUM(K34:L34) -> 0 | N34: =SUM(E34,H34,K34) -> 0 | O34: =SUM(F34,I34,L34) -> 0 | P34: =SUM(G34,J34,M34) -> 10314
B35: 5 | C35: MAGSINO CHOKDEE ECOCARE FARM | D35: NO RECORD SUBMITTED | G35: =SUM(E35:F35) -> 0 | J35: =SUM(H35:I35) -> 0 | M35: =SUM(K35:L35) -> 0 | N35: =SUM(E35,H35,K35) -> 0 | O35: =SUM(F35,I35,L35) -> 0 | P35: =SUM(G35,J35,M35) -> 0
B36: 6 | C36: MOLINO NATURE PARK | G36: 1854 | J36: =SUM(H36:I36) -> 0 | M36: =SUM(K36:L36) -> 0 | N36: =SUM(E36,H36,K36) -> 0 | O36: =SUM(F36,I36,L36) -> 0 | P36: =SUM(G36,J36,M36) -> 1854
C37: EVENTS | G37: =SUM(E37:F37) -> 0 | J37: =SUM(H37:I37) -> 0 | M37: =SUM(K37:L37) -> 0 | N37: =SUM(E37,H37,K37) -> 0 | O37: =SUM(F37,I37,L37) -> 0 | P37: =SUM(G37,J37,M37) -> 0
B38: Total of this Month **** | E38: =SUM(E15:E37) -> 998 | F38: =SUM(F15:F37) -> 1064 | G38: =SUM(G15:G37) -> 31048 | H38: =SUM(H15:H37) -> 0 | I38: =SUM(I15:I37) -> 0 | J38: =SUM(J15:J37) -> 0 | K38: =SUM(K15:K37) -> 0 | L38: =SUM(L15:L37) -> 0 | ... P38: =SUM(P15:P37) -> 31048
B39: Note: *Total number must be recorded, ** Sex & ***Residence entries are optional. Total number of this month must be reported.
B40: OVERNIGHT ARRIVALS
B41: Date | D41: 45839
C42: Accommodation Establishment | D42: Attraction Code | E42: (5) Number of Guests Check IN (unit: visitors) | F42: (6) Number of Guests staying over-night (Guest Nights) | G42: (7) Number of Rooms Occupied by Guests (unit: rooms) | H42: Average Guest/Night | I42: Average Room Occupancy Rate
B45: 1 | C45: ALVEZ LODGE & RESTAURANT | F45: 424 | G45: 212
...

Sheet AUGUST 2025
B1: Tourism Attraction Visitor Record | P1: (VAR 1)
B2: ( This recording form can be used instead of just counting the visitors )
F4: Month/Year: | H4: 45870
F5: Name of City/Municipality: | H5: BALAYAN, BATANGAS
F6: Name of attraction/ Spot:
E8: Type of Tourism Attraction:
B10: DAYTOUR ARRIVALS
B11: Date | E11: *** Place of Residence | N11: * Grand Total Number of Visitors
C12: Accommodation Establishment | E12: Philippines | K12: Foreign Country Residence
E13: This province | H13: Other Province
D14: Attraction Code | E14: Male | F14: Female | G14: Total | H14: Male | I14: Female | J14: Total | K14: Male | L14: Female | M14: Total | N14: Male | O14: Female | P14: Total
B15: 1 | C15: AURORA RESORT | D15: NO RECORD SUBMITTED | G15: 0 | J15: 0 | K15: 0 | L15: 0 | M15: =SUM(K15:L15) -> 0 | N15: =SUM(E15,H15,K15) -> 0 | O15: =SUM(F15,I15,L15) -> 0 | P15: =SUM(G15,J15,M15) -> 0
B16: 2 | C16: ALTINA BEACH HOUSE | D16: NO RECORD SUBMITTED | G16: 0 | J16: 0 | K16: 0 | L16: 0 | M16: =SUM(K16:L16) -> 0 | N16: =SUM(E16,H16,K16) -> 0 | O16: =SUM(F16,I16,L16) -> 0 | P16: =SUM(G16,J16,M16) -> 0
B17: 3 | C17: CHRISOVA RESORT | E17: 49 | F17: 47 | G17: 96 | J17: 0 | K17: 0 | L17: 0 | M17: =SUM(K17:L17) -> 0 | N17: =SUM(E17,H17,K17) -> 49 | O17: =SUM(F17,I17,L17) -> 47 | P17: =SUM(G17,J17,M17) -> 96
B18: 4 | C18: DARLING ANGEL RESORT | E18: 128 | F18: 126 | G18: 254 | J18: 0 | K18: 0 | L18: 0 | M18: =SUM(K18:L18) -> 0 | N18: =SUM(E18,H18,K18) -> 128 | O18: =SUM(F18,I18,L18) -> 126 | P18: =SUM(G18,J18,M18) -> 254
B19: 5 | C19: EASTERN STAR RESORT & INNS INC | G19: 60 | J19: 0 | K19: 0 | L19: 0 | M19: =SUM(K19:L19) -> 0 | N19: =SUM(E19,H19,K19) -> 0 | O19: =SUM(F19,I19,L19) -> 0 | P19: =SUM(G19,J19,M19) -> 60
B20: 6 | C20: KING & QUEEN RESORT | D20: NO RECORD SUBMITTED | G20: 0 | J20: 0 | K20: 0 | L20: 0 | M20: =SUM(K20:L20) -> 0 | N20: =SUM(E20,H20,K20) -> 0 | O20: =SUM(F20,I20,L20) -> 0 | P20: =SUM(G20,J20,M20) -> 0
B21: 7 | C21: LA GEORGINA RESORT | D21: NO RECORD SUBMITTED | G21: 0 | J21: 0 | K21: 0 | L21: 0 | M21: =SUM(K21:L21) -> 0 | N21: =SUM(E21,H21,K21) -> 0 | O21: =SUM(F21,I21,L21) -> 0 | P21: =SUM(G21,J21,M21) -> 0
B22: 8 | C22: LA PISCINA DI CONCEPCION RESORT | D22: NO RECORD SUBMITTED | G22: 0 | J22: 0 | K22: 0 | L22: 0 | M22: =SUM(K22:L22) -> 0 | N22: =SUM(E22,H22,K22) -> 0 | O22: =SUM(F22,I22,L22) -> 0 | P22: =SUM(G22,J22,M22) -> 0
B23: 9 | C23: MALABANAN SWIMMING POOL | D23: NO RECORD SUBMITTED | G23: 0 | J23: 0 | K23: 0 | L23: 0 | M23: =SUM(K23:L23) -> 0 | N23: =SUM(E23,H23,K23) -> 0 | O23: =SUM(F23,I23,L23) -> 0 | P23: =SUM(G23,J23,M23) -> 0
B24: 10 | C24: MY PLACE RESORT & PAVILLION | D24: NO RECORD SUBMITTED | G24: 0 | J24: 0 | K24: 0 | L24: 0 | M24: =SUM(K24:L24) -> 0 | N24: =SUM(E24,H24,K24) -> 0 | O24: =SUM(F24,I24,L24) -> 0 | P24: =SUM(G24,J24,M24) -> 0
B25: 11 | C25: VADZ CASTILLO RESIDENCE | E25: 32 | F25: 25 | G25: 57 | J25: 0 | K25: 0 | L25: 0 | M25: =SUM(K25:L25) -> 0 | N25: =SUM(E25,H25,K25) -> 32 | O25: =SUM(F25,I25,L25) -> 25 | P25: =SUM(G25,J25,M25) -> 57
B26: 12 | C26: VIKTORIA'S GARDEN RESORT | E26: 84 | F26: 72 | G26: 156 | J26: 0 | K26: 0 | L26: 0 | M26: =SUM(K26:L26) -> 0 | N26: =SUM(E26,H26,K26) -> 84 | O26: =SUM(F26,I26,L26) -> 72 | P26: =SUM(G26,J26,M26) -> 156
B27: 13 | C27: VILLA BEADOY RESORT & PAVILLION | E27: 418 | F27: 511 | G27: 929 | J27: 0 | K27: 0 | L27: 0 | M27: =SUM(K27:L27) -> 0 | N27: =SUM(E27,H27,K27) -> 418 | O27: =SUM(F27,I27,L27) -> 511 | P27: =SUM(G27,J27,M27) -> 929
B28: 14 | C28: VILLA SCARLET GARDEN RESORT | E28: 101 | F28: 52 | G28: =SUM(E28:F28) -> 153 | J28: =SUM(H28:I28) -> 0 | K28: 0 | L28: 0 | M28: =SUM(K28:L28) -> 0 | N28: =SUM(E28,H28,K28) -> 101 | O28: =SUM(F28,I28,L28) -> 52 | P28: =SUM(G28,J28,M28) -> 153
B29: 15 | C29: SOGGIORNS | E29: 23 | F29: 32 | G29: 56 | J29: =SUM(H29:I29) -> 0 | K29: 0 | L29: 0 | M29: =SUM(K29:L29) -> 0 | N29: =SUM(E29,H29,K29) -> 23 | O29: =SUM(F29,I29,L29) -> 32 | P29: =SUM(G29,J29,M29) -> 56
C30: TOURIST ATTRACTIONS
B31: 1 | C31: ATHENA RIVER RESORT | D31: NO RECORD SUBMITTED | G31: 0 | J31: =SUM(H31:I31) -> 0 | K31: 0 | L31: 0 | M31: =SUM(K31:L31) -> 0 | N31: =SUM(E31,H31,K31) -> 0 | O31: =SUM(F31,I31,L31) -> 0 | P31: =SUM(G31,J31,M31) -> 0
B32: 2 | C32: BALAYAN BAYWALK | G32: 16482 | J32: =SUM(H32:I32) -> 0 | K32: 0 | L32: 0 | M32: =SUM(K32:L32) -> 0 | N32: =SUM(E32,H32,K32) -> 0 | O32: =SUM(F32,I32,L32) -> 0 | P32: =SUM(G32,J32,M32) -> 16482
B33: 3 | C33: EL SENOR TRES CAIDAS CHAPEL | G33: 2356 | J33: =SUM(H33:I33) -> 0 | K33: 0 | L33: 0 | M33: =SUM(K33:L33) -> 0 | N33: =SUM(E33,H33,K33) -> 0 | O33: =SUM(F33,I33,L33) -> 0 | P33: =SUM(G33,J33,M33) -> 2356
B34: 4 | C34: IMMACULATE CONCEPTION PARISH | G34: 12176 | J34: =SUM(H34:I34) -> 0 | K34: 0 | L34: 0 | M34: =SUM(K34:L34) -> 0 | N34: =SUM(E34,H34,K34) -> 0 | O34: =SUM(F34,I34,L34) -> 0 | P34: =SUM(G34,J34,M34) -> 12176
B35: 5 | C35: MAGSINO CHOKDEE ECOCARE FARM | D35: NO RECORD SUBMITTED | G35: 0 | J35: =SUM(H35:I35) -> 0 | M35: =SUM(K35:L35) -> 0 | N35: =SUM(E35,H35,K35) -> 0 | O35: =SUM(F35,I35,L35) -> 0 | P35: =SUM(G35,J35,M35) -> 0
B36: 6 | C36: MOLINO NATURE PARK | G36: 2186 | J36: =SUM(H36:I36) -> 0 | K36: 0 | L36: 0 | M36: =SUM(K36:L36) -> 0 | N36: =SUM(E36,H36,K36) -> 0 | O36: =SUM(F36,I36,L36) -> 0 | P36: =SUM(G36,J36,M36) -> 2186
C37: EVENTS | G37: =SUM(E37:F37) -> 0 | J37: =SUM(H37:I37) -> 0 | M37: =SUM(K37:L37) -> 0 | N37: =SUM(E37,H37,K37) -> 0 | O37: =SUM(F37,I37,L37) -> 0 | P37: =SUM(G37,J37,M37) -> 0
B38: Total of this Month **** | E38: =SUM(E15:E37) -> 835 | F38: =SUM(F15:F37) -> 865 | G38: =SUM(G15:G37) -> 34961 | H38: =SUM(H15:H37) -> 0 | I38: =SUM(I15:I37) -> 0 | J38: =SUM(J15:J37) -> 0 | K38: =SUM(K15:K37) -> 0 | L38: =SUM(L15:L37) -> 0 | ... P38: =SUM(P15:P37) -> 34961
B39: Note: *Total number must be recorded, ** Sex & ***Residence entries are optional. Total number of this month must be reported.
B40: OVERNIGHT ARRIVALS
B41: Date | D41: 45870
C42: Accommodation Establishment | D42: Attraction Code | E42: (5) Number of Guests Check IN (unit: visitors) | F42: (6) Number of Guests staying over-night (Guest Nights) | G42: (7) Number of Rooms Occupied by Guests (unit: rooms) | H42: Average Guest/Night | I42: Average Room Occupancy Rate
B45: 1 | C45: ALVEZ LODGE & RESTAURANT | F45: 1012 | G45: 506
...

Sheet SEPTEMBER 2025
B1: Tourism Attraction Visitor Record | P1: (VAR 1)
B2: ( This recording form can be used instead of just counting the visitors )
F4: Month/Year: | H4: 45901
F5: Name of City/Municipality: | H5: BALAYAN, BATANGAS
F6: Name of attraction/ Spot:
E8: Type of Tourism Attraction:
B10: DAYTOUR ARRIVALS
B11: Date | E11: *** Place of Residence | N11: * Grand Total Number of Visitors
C12: Accommodation Establishment | E12: Philippines | K12: Foreign Country Residence
E13: This province | H13: Other Province
D14: Attraction Code | E14: Male | F14: Female | G14: Total | H14: Male | I14: Female | J14: Total | K14: Male | L14: Female | M14: Total | N14: Male | O14: Female | P14: Total
B15: 1 | C15: AURORA RESORT | D15: NO RECORD SUBMITTED | G15: 0 | J15: 0 | K15: 0 | L15: 0 | M15: =SUM(K15:L15) -> 0 | N15: =SUM(E15,H15,K15) -> 0 | O15: =SUM(F15,I15,L15) -> 0 | P15: =SUM(G15,J15,M15) -> 0
B16: 2 | C16: ALTINA BEACH HOUSE | D16: NO RECORD SUBMITTED | G16: 0 | J16: 0 | K16: 0 | L16: 0 | M16: =SUM(K16:L16) -> 0 | N16: =SUM(E16,H16,K16) -> 0 | O16: =SUM(F16,I16,L16) -> 0 | P16: =SUM(G16,J16,M16) -> 0
B17: 3 | C17: CHRISOVA RESORT | E17: 34 | F17: 60 | G17: 94 | J17: 0 | K17: 0 | L17: 0 | M17: =SUM(K17:L17) -> 0 | N17: =SUM(E17,H17,K17) -> 34 | O17: =SUM(F17,I17,L17) -> 60 | P17: =SUM(G17,J17,M17) -> 94
B18: 4 | C18: DARLING ANGEL RESORT | E18: 76 | F18: 80 | G18: 156 | J18: 0 | K18: 0 | L18: 0 | M18: =SUM(K18:L18) -> 0 | N18: =SUM(E18,H18,K18) -> 76 | O18: =SUM(F18,I18,L18) -> 80 | P18: =SUM(G18,J18,M18) -> 156
B19: 5 | C19: EASTERN STAR RESORT & INNS INC | G19: 235 | J19: 0 | K19: 0 | L19: 0 | M19: =SUM(K19:L19) -> 0 | N19: =SUM(E19,H19,K19) -> 0 | O19: =SUM(F19,I19,L19) -> 0 | P19: =SUM(G19,J19,M19) -> 235
B20: 6 | C20: KING & QUEEN RESORT | D20: NO RECORD SUBMITTED | G20: 0 | J20: 0 | K20: 0 | L20: 0 | M20: =SUM(K20:L20) -> 0 | N20: =SUM(E20,H20,K20) -> 0 | O20: =SUM(F20,I20,L20) -> 0 | P20: =SUM(G20,J20,M20) -> 0
B21: 7 | C21: LA GEORGINA RESORT | D21: NO RECORD SUBMITTED | G21: 0 | J21: 0 | K21: 0 | L21: 0 | M21: =SUM(K21:L21) -> 0 | N21: =SUM(E21,H21,K21) -> 0 | O21: =SUM(F21,I21,L21) -> 0 | P21: =SUM(G21,J21,M21) -> 0
B22: 8 | C22: LA PISCINA DI CONCEPCION RESORT | D22: NO RECORD SUBMITTED | G22: 0 | J22: 0 | K22: 0 | L22: 0 | M22: =SUM(K22:L22) -> 0 | N22: =SUM(E22,H22,K22) -> 0 | O22: =SUM(F22,I22,L22) -> 0 | P22: =SUM(G22,J22,M22) -> 0
B23: 9 | C23: MALABANAN SWIMMING POOL | D23: NO RECORD SUBMITTED | G23: 0 | J23: 0 | K23: 0 | L23: 0 | M23: =SUM(K23:L23) -> 0 | N23: =SUM(E23,H23,K23) -> 0 | O23: =SUM(F23,I23,L23) -> 0 | P23: =SUM(G23,J23,M23) -> 0
B24: 10 | C24: MY PLACE RESORT & PAVILLION | G24: 0 | J24: 0 | K24: 0 | L24: 0 | M24: =SUM(K24:L24) -> 0 | N24: =SUM(E24,H24,K24) -> 0 | O24: =SUM(F24,I24,L24) -> 0 | P24: =SUM(G24,J24,M24) -> 0
B25: 11 | C25: VADZ CASTILLO RESIDENCE | D25: NO RECORD SUBMITTED | G25: 0 | J25: 0 | K25: 0 | L25: 0 | M25: =SUM(K25:L25) -> 0 | N25: =SUM(E25,H25,K25) -> 0 | O25: =SUM(F25,I25,L25) -> 0 | P25: =SUM(G25,J25,M25) -> 0
B26: 12 | C26: VIKTORIA'S GARDEN RESORT | E26: 212 | F26: 182 | G26: 394 | J26: 0 | K26: 0 | L26: 0 | M26: =SUM(K26:L26) -> 0 | N26: =SUM(E26,H26,K26) -> 212 | O26: =SUM(F26,I26,L26) -> 182 | P26: =SUM(G26,J26,M26) -> 394
B27: 13 | C27: VILLA BEADOY RESORT & PAVILLION | E27: 341 | F27: 380 | G27: 730 | J27: 0 | K27: 0 | L27: 0 | M27: =SUM(K27:L27) -> 0 | N27: =SUM(E27,H27,K27) -> 341 | O27: =SUM(F27,I27,L27) -> 380 | P27: =SUM(G27,J27,M27) -> 730
B28: 14 | C28: VILLA SCARLET GARDEN RESORT | D28: NO RECORD SUBMITTED | G28: 0 | J28: 0 | K28: 0 | L28: 0 | M28: =SUM(K28:L28) -> 0 | N28: =SUM(E28,H28,K28) -> 0 | O28: =SUM(F28,I28,L28) -> 0 | P28: =SUM(G28,J28,M28) -> 0
B29: 15 | C29: SOGGIORNS | E29: 12 | F29: 11 | G29: 24 | J29: 0 | K29: 0 | L29: 0 | M29: =SUM(K29:L29) -> 0 | N29: =SUM(E29,H29,K29) -> 12 | O29: =SUM(F29,I29,L29) -> 11 | P29: =SUM(G29,J29,M29) -> 24
C30: TOURIST ATTRACTIONS
B31: 1 | C31: ATHENA RIVER RESORT | D31: NO RECORD SUBMITTED | G31: 0 | J31: 0 | K31: 0 | L31: 0 | M31: =SUM(K31:L31) -> 0 | N31: =SUM(E31,H31,K31) -> 0 | O31: =SUM(F31,I31,L31) -> 0 | P31: =SUM(G31,J31,M31) -> 0
B32: 2 | C32: BALAYAN BAYWALK | G32: 9356 | J32: 0 | K32: 0 | L32: 0 | M32: =SUM(K32:L32) -> 0 | N32: =SUM(E32,H32,K32) -> 0 | O32: =SUM(F32,I32,L32) -> 0 | P32: =SUM(G32,J32,M32) -> 9356
B33: 3 | C33: EL SENOR TRES CAIDAS CHAPEL | G33: 1894 | J33: 0 | K33: 0 | L33: 0 | M33: =SUM(K33:L33) -> 0 | N33: =SUM(E33,H33,K33) -> 0 | O33: =SUM(F33,I33,L33) -> 0 | P33: =SUM(G33,J33,M33) -> 1894
B34: 4 | C34: IMMACULATE CONCEPTION PARISH | G34: 13007 | J34: 0 | K34: 0 | L34: 0 | M34: =SUM(K34:L34) -> 0 | N34: =SUM(E34,H34,K34) -> 0 | O34: =SUM(F34,I34,L34) -> 0 | P34: =SUM(G34,J34,M34) -> 13007
B35: 5 | C35: MAGSINO CHOKDEE ECOCARE FARM | D35: NO RECORD SUBMITTED | G35: 0 | J35: 0 | K35: 0 | L35: 0 | M35: =SUM(K35:L35) -> 0 | N35: =SUM(E35,H35,K35) -> 0 | O35: =SUM(F35,I35,L35) -> 0 | P35: =SUM(G35,J35,M35) -> 0
B36: 6 | C36: MOLINO NATURE PARK | G36: 782 | J36: 0 | K36: 0 | L36: 0 | M36: =SUM(K36:L36) -> 0 | N36: =SUM(E36,H36,K36) -> 0 | O36: =SUM(F36,I36,L36) -> 0 | P36: =SUM(G36,J36,M36) -> 782
C37: EVENTS | G37: =SUM(E37:F37) -> 0
B38: Total of this Month **** | E38: =SUM(E15:E37) -> 675 | F38: =SUM(F15:F37) -> 713 | G38: =SUM(G15:G37) -> 26672 | H38: =SUM(H15:H37) -> 0 | I38: =SUM(I15:I37) -> 0 | J38: =SUM(J15:J37) -> 0 | K38: =SUM(K15:K37) -> 0 | L38: =SUM(L15:L37) -> 0 | ... P38: =SUM(P15:P37) -> 26672
B39: Note: *Total number must be recorded, ** Sex & ***Residence entries are optional. Total number of this month must be reported.
B40: OVERNIGHT ARRIVALS
B41: Date | D41: 45901
C42: Accommodation Establishment | D42: Attraction Code | E42: (5) Number of Guests Check IN (unit: visitors) | F42: (6) Number of Guests staying over-night (Guest Nights) | G42: (7) Number of Rooms Occupied by Guests (unit: rooms) | H42: Average Guest/Night | I42: Average Room Occupancy Rate
B45: 1 | C45: ALVEZ LODGE & RESTAURANT | F45: 924 | G45: 462
...

Sheet OCTOBER 2025
B1: Tourism Attraction Visitor Record | P1: (VAR 1)
B2: ( This recording form can be used instead of just counting the visitors )
F4: Month/Year: | H4: 45931
F5: Name of City/Municipality: | H5: BALAYAN, BATANGAS
F6: Name of attraction/ Spot:
E8: Type of Tourism Attraction:
B10: DAYTOUR ARRIVALS
B11: Date | E11: *** Place of Residence | N11: * Grand Total Number of Visitors
C12: Accommodation Establishment | E12: Philippines | K12: Foreign Country Residence
E13: This province | H13: Other Province
D14: Attraction Code | E14: Male | F14: Female | G14: Total | H14: Male | I14: Female | J14: Total | K14: Male | L14: Female | M14: Total | N14: Male | O14: Female | P14: Total
B15: 1 | C15: AURORA RESORT | D15: NO RECORD SUBMITTED | G15: 0 | J15: 0 | K15: 0 | L15: 0 | M15: =SUM(K15:L15) -> 0 | N15: =SUM(E15,H15,K15) -> 0 | O15: =SUM(F15,I15,L15) -> 0 | P15: =SUM(G15,J15,M15) -> 0
B16: 2 | C16: ALTINA BEACH HOUSE | D16: NO RECORD SUBMITTED | G16: 0 | J16: 0 | K16: 0 | L16: 0 | M16: =SUM(K16:L16) -> 0 | N16: =SUM(E16,H16,K16) -> 0 | O16: =SUM(F16,I16,L16) -> 0 | P16: =SUM(G16,J16,M16) -> 0
B17: 3 | C17: CHRISOVA RESORT | D17: NO RECORD SUBMITTED | G17: 0 | J17: 0 | K17: 0 | L17: 0 | M17: =SUM(K17:L17) -> 0 | N17: =SUM(E17,H17,K17) -> 0 | O17: =SUM(F17,I17,L17) -> 0 | P17: =SUM(G17,J17,M17) -> 0
B18: 4 | C18: DARLING ANGEL RESORT | E18: 214 | F18: 189 | G18: 403 | J18: 0 | K18: 0 | L18: 0 | M18: =SUM(K18:L18) -> 0 | N18: =SUM(E18,H18,K18) -> 214 | O18: =SUM(F18,I18,L18) -> 189 | P18: =SUM(G18,J18,M18) -> 403
B19: 5 | C19: EASTERN STAR RESORT & INNS INC | G19: 837 | J19: 0 | K19: 0 | L19: 0 | M19: =SUM(K19:L19) -> 0 | N19: =SUM(E19,H19,K19) -> 0 | O19: =SUM(F19,I19,L19) -> 0 | P19: =SUM(G19,J19,M19) -> 837
B20: 6 | C20: KING & QUEEN RESORT | D20: NO RECORD SUBMITTED | G20: 0 | J20: 0 | K20: 0 | L20: 0 | M20: =SUM(K20:L20) -> 0 | N20: =SUM(E20,H20,K20) -> 0 | O20: =SUM(F20,I20,L20) -> 0 | P20: =SUM(G20,J20,M20) -> 0
B21: 7 | C21: LA GEORGINA RESORT | D21: NO RECORD SUBMITTED | G21: 0 | J21: 0 | K21: 0 | L21: 0 | M21: =SUM(K21:L21) -> 0 | N21: =SUM(E21,H21,K21) -> 0 | O21: =SUM(F21,I21,L21) -> 0 | P21: =SUM(G21,J21,M21) -> 0
B22: 8 | C22: LA PISCINA DI CONCEPCION RESORT | D22: NO RECORD SUBMITTED | G22: 0 | J22: 0 | K22: 0 | L22: 0 | M22: =SUM(K22:L22) -> 0 | N22: =SUM(E22,H22,K22) -> 0 | O22: =SUM(F22,I22,L22) -> 0 | P22: =SUM(G22,J22,M22) -> 0
B23: 9 | C23: MALABANAN SWIMMING POOL | D23: NO RECORD SUBMITTED | G23: 0 | J23: 0 | K23: 0 | L23: 0 | M23: =SUM(K23:L23) -> 0 | N23: =SUM(E23,H23,K23) -> 0 | O23: =SUM(F23,I23,L23) -> 0 | P23: =SUM(G23,J23,M23) -> 0
B24: 10 | C24: MY PLACE RESORT & PAVILLION | D24: NO RECORD SUBMITTED | G24: 0 | J24: 0 | K24: 0 | L24: 0 | M24: =SUM(K24:L24) -> 0 | N24: =SUM(E24,H24,K24) -> 0 | O24: =SUM(F24,I24,L24) -> 0 | P24: =SUM(G24,J24,M24) -> 0
B25: 11 | C25: VADZ CASTILLO RESIDENCE | D25: NO RECORD SUBMITTED | G25: 0 | J25: 0 | K25: 0 | L25: 0 | M25: =SUM(K25:L25) -> 0 | N25: =SUM(E25,H25,K25) -> 0 | O25: =SUM(F25,I25,L25) -> 0 | P25: =SUM(G25,J25,M25) -> 0
B26: 12 | C26: VIKTORIA'S GARDEN RESORT | D26: NO RECORD SUBMITTED | G26: 0 | J26: 0 | K26: 0 | L26: 0 | M26: =SUM(K26:L26) -> 0 | N26: =SUM(E26,H26,K26) -> 0 | O26: =SUM(F26,I26,L26) -> 0 | P26: =SUM(G26,J26,M26) -> 0
B27: 13 | C27: VILLA BEADOY RESORT & PAVILLION | E27: 585 | F27: 589 | G27: 1174 | J27: 0 | K27: 0 | L27: 0 | M27: =SUM(K27:L27) -> 0 | N27: =SUM(E27,H27,K27) -> 585 | O27: =SUM(F27,I27,L27) -> 589 | P27: =SUM(G27,J27,M27) -> 1174
B28: 14 | C28: VILLA SCARLET GARDEN RESORT | D28: NO RECORD SUBMITTED | G28: 0 | J28: 0 | K28: 0 | L28: 0 | M28: =SUM(K28:L28) -> 0 | N28: =SUM(E28,H28,K28) -> 0 | O28: =SUM(F28,I28,L28) -> 0 | P28: =SUM(G28,J28,M28) -> 0
B29: 15 | C29: SOGGIORNS | E29: 17 | F29: 30 | G29: 47 | J29: 0 | K29: 0 | L29: 0 | M29: =SUM(K29:L29) -> 0 | N29: =SUM(E29,H29,K29) -> 17 | O29: =SUM(F29,I29,L29) -> 30 | P29: =SUM(G29,J29,M29) -> 47
C30: TOURIST ATTRACTIONS
B31: 1 | C31: ATHENA RIVER RESORT | G31: 0 | J31: 0 | K31: 0 | L31: 0 | M31: =SUM(K31:L31) -> 0 | N31: =SUM(E31,H31,K31) -> 0 | O31: =SUM(F31,I31,L31) -> 0 | P31: =SUM(G31,J31,M31) -> 0
B32: 2 | C32: BALAYAN BAYWALK | G32: 4789 | J32: 0 | K32: 0 | L32: 0 | M32: =SUM(K32:L32) -> 0 | N32: =SUM(E32,H32,K32) -> 0 | O32: =SUM(F32,I32,L32) -> 0 | P32: =SUM(G32,J32,M32) -> 4789
B33: 3 | C33: EL SENOR TRES CAIDAS CHAPEL | G33: 2893 | J33: 0 | K33: 0 | L33: 0 | M33: =SUM(K33:L33) -> 0 | N33: =SUM(E33,H33,K33) -> 0 | O33: =SUM(F33,I33,L33) -> 0 | P33: =SUM(G33,J33,M33) -> 2893
B34: 4 | C34: IMMACULATE CONCEPTION PARISH | G34: 11678 | J34: 0 | K34: 0 | L34: 0 | M34: =SUM(K34:L34) -> 0 | N34: =SUM(E34,H34,K34) -> 0 | O34: =SUM(F34,I34,L34) -> 0 | P34: =SUM(G34,J34,M34) -> 11678
B35: 5 | C35: MAGSINO CHOKDEE ECOCARE FARM | G35: 0 | J35: 0 | K35: 0 | L35: 0 | M35: =SUM(K35:L35) -> 0 | N35: =SUM(E35,H35,K35) -> 0 | O35: =SUM(F35,I35,L35) -> 0 | P35: =SUM(G35,J35,M35) -> 0
B36: 6 | C36: MOLINO NATURE PARK | G36: 0 | J36: 0 | K36: 0 | L36: 0 | M36: =SUM(K36:L36) -> 0 | N36: =SUM(E36,H36,K36) -> 0 | O36: =SUM(F36,I36,L36) -> 0 | P36: =SUM(G36,J36,M36) -> 0
